<?xml version="1.0" ?>
<!-- =================================================================================== -->
<!-- |    This document was autogenerated by xacro from testbot.xacro                  | -->
<!-- |    EDITING THIS FILE BY HAND IS NOT RECOMMENDED                                 | -->
<!-- =================================================================================== -->
<robot name="testbot">
  <material name="silver">
    <color rgba="0.700 0.700 0.700 1.000"/>
  </material>
  <transmission name="Rev1_tran">
    <type>transmission_interface/SimpleTransmission</type>
    <joint name="Rev1">
      <hardwareInterface>hardware_interface/EffortJointInterface</hardwareInterface>
    </joint>
    <actuator name="Rev1_actr">
      <hardwareInterface>hardware_interface/EffortJointInterface</hardwareInterface>
      <mechanicalReduction>1</mechanicalReduction>
    </actuator>
  </transmission>
  <transmission name="Rev2_tran">
    <type>transmission_interface/SimpleTransmission</type>
    <joint name="Rev2">
      <hardwareInterface>hardware_interface/EffortJointInterface</hardwareInterface>
    </joint>
    <actuator name="Rev2_actr">
      <hardwareInterface>hardware_interface/EffortJointInterface</hardwareInterface>
      <mechanicalReduction>1</mechanicalReduction>
    </actuator>
  </transmission>
  <transmission name="Rev3_tran">
    <type>transmission_interface/SimpleTransmission</type>
    <joint name="Rev3">
      <hardwareInterface>hardware_interface/EffortJointInterface</hardwareInterface>
    </joint>
    <actuator name="Rev3_actr">
      <hardwareInterface>hardware_interface/EffortJointInterface</hardwareInterface>
      <mechanicalReduction>1</mechanicalReduction>
    </actuator>
  </transmission>
  <transmission name="Rev4_tran">
    <type>transmission_interface/SimpleTransmission</type>
    <joint name="Rev4">
      <hardwareInterface>hardware_interface/EffortJointInterface</hardwareInterface>
    </joint>
    <actuator name="Rev4_actr">
      <hardwareInterface>hardware_interface/EffortJointInterface</hardwareInterface>
      <mechanicalReduction>1</mechanicalReduction>
    </actuator>
  </transmission>
  <gazebo>
    <plugin filename="libgazebo_ros_control.so" name="control"/>
  </gazebo>
  <gazebo reference="base_link">
    <material>Gazebo/Silver</material>
    <mu1>0.2</mu1>
    <mu2>0.2</mu2>
    <selfCollide>true</selfCollide>
    <gravity>true</gravity>
  </gazebo>
  <gazebo reference="motor_planetary_p2_v1_2">
    <material>Gazebo/Silver</material>
    <mu1>0.2</mu1>
    <mu2>0.2</mu2>
    <selfCollide>true</selfCollide>
  </gazebo>
  <gazebo reference="motor_planetary_p2_v1_4">
    <material>Gazebo/Silver</material>
    <mu1>0.2</mu1>
    <mu2>0.2</mu2>
    <selfCollide>true</selfCollide>
  </gazebo>
  <gazebo reference="motor_planetary_p2_v1_1">
    <material>Gazebo/Silver</material>
    <mu1>0.2</mu1>
    <mu2>0.2</mu2>
    <selfCollide>true</selfCollide>
  </gazebo>
  <gazebo reference="motor_planetary_p2_v1_3">
    <material>Gazebo/Silver</material>
    <mu1>0.2</mu1>
    <mu2>0.2</mu2>
    <selfCollide>true</selfCollide>
  </gazebo>
  <link name="base_link">
    <inertial>
      <origin rpy="0 0 0" xyz="0.0 0.0 0.0"/>
      <mass value="0.0"/>
      <inertia ixx="0.0" ixy="0.0" ixz="0.0" iyy="0.0" iyz="0.0" izz="0.0"/>
    </inertial>
    <visual>
      <origin rpy="0 0 0" xyz="0 0 0"/>
      <geometry>
        <mesh filename="package://description/meshes/base_link.stl" scale="0.001 0.001 0.001"/>
      </geometry>
      <material name="silver"/>
    </visual>
    <collision>
      <origin rpy="0 0 0" xyz="0 0 0"/>
      <geometry>
        <mesh filename="package://description/meshes/base_link.stl" scale="0.001 0.001 0.001"/>
      </geometry>
    </collision>
  </link>
  <link name="motor_planetary_p2_v1_2">
    <inertial>
      <origin rpy="0 0 0" xyz="0.04118987844170208 -8.108254794692016e-06 0.000250596805274686"/>
      <mass value="2.3755553699222616"/>
      <inertia ixx="0.007233" ixy="-1e-06" ixz="1.2e-05" iyy="0.003977" iyz="0.0" izz="0.003976"/>
    </inertial>
    <visual>
      <origin rpy="0 0 0" xyz="-0.756732 -0.151207 -0.067818"/>
      <geometry>
        <mesh filename="package://description/meshes/motor_planetary_p2_v1_2.stl" scale="0.001 0.001 0.001"/>
      </geometry>
      <material name="silver"/>
    </visual>
    <collision>
      <origin rpy="0 0 0" xyz="-0.756732 -0.151207 -0.067818"/>
      <geometry>
        <mesh filename="package://description/meshes/motor_planetary_p2_v1_2.stl" scale="0.001 0.001 0.001"/>
      </geometry>
    </collision>
  </link>
  <link name="motor_planetary_p2_v1_4">
    <inertial>
      <origin rpy="0 0 0" xyz="0.0001313422839553935 0.041189495140773136 -0.00020947496986596648"/>
      <mass value="2.3755553699222616"/>
      <inertia ixx="0.003977" ixy="6e-06" ixz="1e-06" iyy="0.007233" iyz="-1e-05" izz="0.003976"/>
    </inertial>
    <visual>
      <origin rpy="0 0 0" xyz="-0.350608 -0.27833 -0.067818"/>
      <geometry>
        <mesh filename="package://description/meshes/motor_planetary_p2_v1_4.stl" scale="0.001 0.001 0.001"/>
      </geometry>
      <material name="silver"/>
    </visual>
    <collision>
      <origin rpy="0 0 0" xyz="-0.350608 -0.27833 -0.067818"/>
      <geometry>
        <mesh filename="package://description/meshes/motor_planetary_p2_v1_4.stl" scale="0.001 0.001 0.001"/>
      </geometry>
    </collision>
  </link>
  <link name="motor_planetary_p2_v1_1">
    <inertial>
      <origin rpy="0 0 0" xyz="-0.04118998789165343 0.00021759055173636854 0.00012263260280097332"/>
      <mass value="2.3755553699222616"/>
      <inertia ixx="0.007233" ixy="-1e-05" ixz="-5e-06" iyy="0.003976" iyz="-0.0" izz="0.003977"/>
    </inertial>
    <visual>
      <origin rpy="0 0 0" xyz="-0.223486 0.127794 -0.067818"/>
      <geometry>
        <mesh filename="package://description/meshes/motor_planetary_p2_v1_1.stl" scale="0.001 0.001 0.001"/>
      </geometry>
      <material name="silver"/>
    </visual>
    <collision>
      <origin rpy="0 0 0" xyz="-0.223486 0.127794 -0.067818"/>
      <geometry>
        <mesh filename="package://description/meshes/motor_planetary_p2_v1_1.stl" scale="0.001 0.001 0.001"/>
      </geometry>
    </collision>
  </link>
  <link name="motor_planetary_p2_v1_3">
    <inertial>
      <origin rpy="0 0 0" xyz="0.0002361733200544336 -0.04118941036184415 -7.71119074641502e-05"/>
      <mass value="2.3755553699222616"/>
      <inertia ixx="0.003976" ixy="-1.1e-05" ixz="0.0" iyy="0.007233" iyz="3e-06" izz="0.003977"/>
    </inertial>
    <visual>
      <origin rpy="0 0 0" xyz="-0.629609 0.254917 -0.067818"/>
      <geometry>
        <mesh filename="package://description/meshes/motor_planetary_p2_v1_3.stl" scale="0.001 0.001 0.001"/>
      </geometry>
      <material name="silver"/>
    </visual>
    <collision>
      <origin rpy="0 0 0" xyz="-0.629609 0.254917 -0.067818"/>
      <geometry>
        <mesh filename="package://description/meshes/motor_planetary_p2_v1_3.stl" scale="0.001 0.001 0.001"/>
      </geometry>
    </collision>
  </link>
  <joint name="Rev1" type="continuous">
    <origin rpy="0 0 0" xyz="0.756732 0.151207 0.067818"/>
    <parent link="base_link"/>
    <child link="motor_planetary_p2_v1_2"/>
    <axis xyz="-1.0 -0.0 -5.9e-05"/>
  </joint>
  <joint name="Rev2" type="continuous">
    <origin rpy="0 0 0" xyz="0.350608 0.27833 0.067818"/>
    <parent link="base_link"/>
    <child link="motor_planetary_p2_v1_4"/>
    <axis xyz="0.0 -1.0 -5.9e-05"/>
  </joint>
  <joint name="Rev3" type="continuous">
    <origin rpy="0 0 0" xyz="0.223486 -0.127794 0.067818"/>
    <parent link="base_link"/>
    <child link="motor_planetary_p2_v1_1"/>
    <axis xyz="1.0 0.0 -5.9e-05"/>
  </joint>
  <joint name="Rev4" type="continuous">
    <origin rpy="0 0 0" xyz="0.629609 -0.254917 0.067818"/>
    <parent link="base_link"/>
    <child link="motor_planetary_p2_v1_3"/>
    <axis xyz="-0.0 1.0 -5.9e-05"/>
  </joint>
</robot>

